[2025-03-08T20:15:58.201+0000] {local_task_job_runner.py:123} INFO - ::group::Pre task execution logs
[2025-03-08T20:15:58.222+0000] {taskinstance.py:2612} INFO - Dependencies all met for dep_context=non-requeueable deps ti=<TaskInstance: pull_data_from_chess_api.load_to_gold_layer manual__2025-03-08T12:43:13.309365+00:00 [queued]>
[2025-03-08T20:15:58.231+0000] {taskinstance.py:2612} INFO - Dependencies all met for dep_context=requeueable deps ti=<TaskInstance: pull_data_from_chess_api.load_to_gold_layer manual__2025-03-08T12:43:13.309365+00:00 [queued]>
[2025-03-08T20:15:58.232+0000] {taskinstance.py:2865} INFO - Starting attempt 22 of 22
[2025-03-08T20:15:58.247+0000] {taskinstance.py:2888} INFO - Executing <Task(PythonOperator): load_to_gold_layer> on 2025-03-08 12:43:13.309365+00:00
[2025-03-08T20:15:58.256+0000] {warnings.py:112} WARNING - /home/***/.local/lib/python3.12/site-packages/***/task/task_runner/standard_task_runner.py:70: DeprecationWarning: This process (pid=5282) is multi-threaded, use of fork() may lead to deadlocks in the child.
  pid = os.fork()

[2025-03-08T20:15:58.258+0000] {standard_task_runner.py:72} INFO - Started process 5283 to run task
[2025-03-08T20:15:58.259+0000] {standard_task_runner.py:104} INFO - Running: ['***', 'tasks', 'run', 'pull_data_from_chess_api', 'load_to_gold_layer', 'manual__2025-03-08T12:43:13.309365+00:00', '--job-id', '437', '--raw', '--subdir', 'DAGS_FOLDER/collect_chess_data_dag.py', '--cfg-path', '/tmp/tmp55db1fmf']
[2025-03-08T20:15:58.260+0000] {standard_task_runner.py:105} INFO - Job 437: Subtask load_to_gold_layer
[2025-03-08T20:15:58.304+0000] {task_command.py:467} INFO - Running <TaskInstance: pull_data_from_chess_api.load_to_gold_layer manual__2025-03-08T12:43:13.309365+00:00 [running]> on host 70b3b9cfbba0
[2025-03-08T20:15:58.393+0000] {taskinstance.py:3131} INFO - Exporting env vars: AIRFLOW_CTX_DAG_OWNER='***' AIRFLOW_CTX_DAG_ID='pull_data_from_chess_api' AIRFLOW_CTX_TASK_ID='load_to_gold_layer' AIRFLOW_CTX_EXECUTION_DATE='2025-03-08T12:43:13.309365+00:00' AIRFLOW_CTX_TRY_NUMBER='22' AIRFLOW_CTX_DAG_RUN_ID='manual__2025-03-08T12:43:13.309365+00:00'
[2025-03-08T20:15:58.394+0000] {taskinstance.py:731} INFO - ::endgroup::
[2025-03-08T20:15:58.408+0000] {logging_mixin.py:190} INFO - Execution Date: 2025-03-08
[2025-03-08T20:15:58.409+0000] {connection.py:531} ERROR - Unable to retrieve connection from secrets backend (EnvironmentVariablesBackend). Checking subsequent secrets backend.
Traceback (most recent call last):
  File "/home/airflow/.local/lib/python3.12/site-packages/airflow/models/connection.py", line 526, in get_connection_from_secrets
    conn = secrets_backend.get_connection(conn_id=conn_id)
           ^^^^^^^^^^^^^^^^^^^^^^^^^^^^^^^^^^^^^^^^^^^^^^^
  File "/home/airflow/.local/lib/python3.12/site-packages/airflow/secrets/base_secrets.py", line 116, in get_connection
    return self.deserialize_connection(conn_id=conn_id, value=value)
           ^^^^^^^^^^^^^^^^^^^^^^^^^^^^^^^^^^^^^^^^^^^^^^^^^^^^^^^^^
  File "/home/airflow/.local/lib/python3.12/site-packages/airflow/secrets/base_secrets.py", line 70, in deserialize_connection
    return Connection(conn_id=conn_id, uri=value)
           ^^^^^^^^^^^^^^^^^^^^^^^^^^^^^^^^^^^^^^
  File "<string>", line 4, in __init__
  File "/home/airflow/.local/lib/python3.12/site-packages/sqlalchemy/orm/state.py", line 481, in _initialize_instance
    with util.safe_reraise():
         ^^^^^^^^^^^^^^^^^^^
  File "/home/airflow/.local/lib/python3.12/site-packages/sqlalchemy/util/langhelpers.py", line 70, in __exit__
    compat.raise_(
  File "/home/airflow/.local/lib/python3.12/site-packages/sqlalchemy/util/compat.py", line 211, in raise_
    raise exception
  File "/home/airflow/.local/lib/python3.12/site-packages/sqlalchemy/orm/state.py", line 479, in _initialize_instance
    return manager.original_init(*mixed[1:], **kwargs)
           ^^^^^^^^^^^^^^^^^^^^^^^^^^^^^^^^^^^^^^^^^^^
  File "/home/airflow/.local/lib/python3.12/site-packages/airflow/models/connection.py", line 169, in __init__
    self._parse_from_uri(uri)
  File "/home/airflow/.local/lib/python3.12/site-packages/airflow/models/connection.py", line 257, in _parse_from_uri
    self.port = uri_parts.port
                ^^^^^^^^^^^^^^
  File "/usr/local/lib/python3.12/urllib/parse.py", line 182, in port
    raise ValueError(f"Port could not be cast to integer value as {port!r}")
ValueError: Port could not be cast to integer value as 'DefaultEndpointsProtocol=https;AccountName=rbchesssa;AccountKey=lG9W+utkpTNorE0rTLlfDMUZsTPleXk6pXv6NnfDTi'
[2025-03-08T20:15:58.421+0000] {base.py:84} INFO - Retrieving connection 'azure_chess_storage'
[2025-03-08T20:16:00.267+0000] {logging_mixin.py:190} INFO -    column00  ...                                          pgn_trans
0         0  ...  1. e4 c6 2. d4 e5 3. Bc4 d5 4. exd5 cxd5 5. Bb...
1         1  ...  1. d4 e5 2. c4 exd4 3. Qxd4 c5 4. Qd1 Nc6 5. N...
2         2  ...  1. e4 e5 2. Nf3 Nc6 3. Bc4 Nf6 4. Ng5 h6 5. Nx...
3         3  ...  1. d4 e5 2. dxe5 Bc5 3. Nc3 Nc6 4. Nf3 Nge7 5....
4         4  ...  1. e4 c5 2. Nf3 d6 3. Bc4 Nd7 4. Ng5 e6 5. Qf3...

[5 rows x 24 columns]
[2025-03-08T20:16:00.269+0000] {logging_mixin.py:190} INFO - Execution Date: 2025-03-08
[2025-03-08T20:16:00.336+0000] {taskinstance.py:3310} ERROR - Task failed with exception
Traceback (most recent call last):
  File "/home/airflow/.local/lib/python3.12/site-packages/airflow/models/taskinstance.py", line 767, in _execute_task
    result = _execute_callable(context=context, **execute_callable_kwargs)
             ^^^^^^^^^^^^^^^^^^^^^^^^^^^^^^^^^^^^^^^^^^^^^^^^^^^^^^^^^^^^^
  File "/home/airflow/.local/lib/python3.12/site-packages/airflow/models/taskinstance.py", line 733, in _execute_callable
    return ExecutionCallableRunner(
           ^^^^^^^^^^^^^^^^^^^^^^^^
  File "/home/airflow/.local/lib/python3.12/site-packages/airflow/utils/operator_helpers.py", line 252, in run
    return self.func(*args, **kwargs)
           ^^^^^^^^^^^^^^^^^^^^^^^^^^
  File "/home/airflow/.local/lib/python3.12/site-packages/airflow/models/baseoperator.py", line 406, in wrapper
    return func(self, *args, **kwargs)
           ^^^^^^^^^^^^^^^^^^^^^^^^^^^
  File "/home/airflow/.local/lib/python3.12/site-packages/airflow/operators/python.py", line 238, in execute
    return_value = self.execute_callable()
                   ^^^^^^^^^^^^^^^^^^^^^^^
  File "/home/airflow/.local/lib/python3.12/site-packages/airflow/operators/python.py", line 256, in execute_callable
    return runner.run(*self.op_args, **self.op_kwargs)
           ^^^^^^^^^^^^^^^^^^^^^^^^^^^^^^^^^^^^^^^^^^^
  File "/home/airflow/.local/lib/python3.12/site-packages/airflow/utils/operator_helpers.py", line 252, in run
    return self.func(*args, **kwargs)
           ^^^^^^^^^^^^^^^^^^^^^^^^^^
  File "/opt/airflow/dags/scripts/python_scripts.py", line 179, in load_to_gold_layer
    columns = [desc[0] for desc in conn.execute("DESCRIBE my_table").fetchall()]
                                   ^^^^^^^^^^^^^^^^^^^^^^^^^^^^^^^^^
duckdb.duckdb.CatalogException: Catalog Error: Table with name my_table does not exist!
Did you mean "pg_tables"?

LINE 1: DESCRIBE my_table
                 ^
[2025-03-08T20:16:00.358+0000] {taskinstance.py:1225} INFO - Marking task as FAILED. dag_id=pull_data_from_chess_api, task_id=load_to_gold_layer, run_id=manual__2025-03-08T12:43:13.309365+00:00, execution_date=20250308T124313, start_date=20250308T201558, end_date=20250308T201600
[2025-03-08T20:16:00.386+0000] {taskinstance.py:340} INFO - ::group::Post task execution logs
[2025-03-08T20:16:00.387+0000] {standard_task_runner.py:124} ERROR - Failed to execute job 437 for task load_to_gold_layer (Catalog Error: Table with name my_table does not exist!
Did you mean "pg_tables"?

LINE 1: DESCRIBE my_table
                 ^; 5283)
Traceback (most recent call last):
  File "/home/airflow/.local/lib/python3.12/site-packages/airflow/task/task_runner/standard_task_runner.py", line 117, in _start_by_fork
    ret = args.func(args, dag=self.dag)
          ^^^^^^^^^^^^^^^^^^^^^^^^^^^^^
  File "/home/airflow/.local/lib/python3.12/site-packages/airflow/cli/cli_config.py", line 49, in command
    return func(*args, **kwargs)
           ^^^^^^^^^^^^^^^^^^^^^
  File "/home/airflow/.local/lib/python3.12/site-packages/airflow/utils/cli.py", line 115, in wrapper
    return f(*args, **kwargs)
           ^^^^^^^^^^^^^^^^^^
  File "/home/airflow/.local/lib/python3.12/site-packages/airflow/cli/commands/task_command.py", line 483, in task_run
    task_return_code = _run_task_by_selected_method(args, _dag, ti)
                       ^^^^^^^^^^^^^^^^^^^^^^^^^^^^^^^^^^^^^^^^^^^^
  File "/home/airflow/.local/lib/python3.12/site-packages/airflow/cli/commands/task_command.py", line 256, in _run_task_by_selected_method
    return _run_raw_task(args, ti)
           ^^^^^^^^^^^^^^^^^^^^^^^
  File "/home/airflow/.local/lib/python3.12/site-packages/airflow/cli/commands/task_command.py", line 341, in _run_raw_task
    return ti._run_raw_task(
           ^^^^^^^^^^^^^^^^^
  File "/home/airflow/.local/lib/python3.12/site-packages/airflow/utils/session.py", line 97, in wrapper
    return func(*args, session=session, **kwargs)
           ^^^^^^^^^^^^^^^^^^^^^^^^^^^^^^^^^^^^^^
  File "/home/airflow/.local/lib/python3.12/site-packages/airflow/models/taskinstance.py", line 3004, in _run_raw_task
    return _run_raw_task(
           ^^^^^^^^^^^^^^
  File "/home/airflow/.local/lib/python3.12/site-packages/airflow/models/taskinstance.py", line 273, in _run_raw_task
    TaskInstance._execute_task_with_callbacks(
  File "/home/airflow/.local/lib/python3.12/site-packages/airflow/models/taskinstance.py", line 3158, in _execute_task_with_callbacks
    result = self._execute_task(context, task_orig)
             ^^^^^^^^^^^^^^^^^^^^^^^^^^^^^^^^^^^^^^
  File "/home/airflow/.local/lib/python3.12/site-packages/airflow/models/taskinstance.py", line 3182, in _execute_task
    return _execute_task(self, context, task_orig)
           ^^^^^^^^^^^^^^^^^^^^^^^^^^^^^^^^^^^^^^^
  File "/home/airflow/.local/lib/python3.12/site-packages/airflow/models/taskinstance.py", line 767, in _execute_task
    result = _execute_callable(context=context, **execute_callable_kwargs)
             ^^^^^^^^^^^^^^^^^^^^^^^^^^^^^^^^^^^^^^^^^^^^^^^^^^^^^^^^^^^^^
  File "/home/airflow/.local/lib/python3.12/site-packages/airflow/models/taskinstance.py", line 733, in _execute_callable
    return ExecutionCallableRunner(
           ^^^^^^^^^^^^^^^^^^^^^^^^
  File "/home/airflow/.local/lib/python3.12/site-packages/airflow/utils/operator_helpers.py", line 252, in run
    return self.func(*args, **kwargs)
           ^^^^^^^^^^^^^^^^^^^^^^^^^^
  File "/home/airflow/.local/lib/python3.12/site-packages/airflow/models/baseoperator.py", line 406, in wrapper
    return func(self, *args, **kwargs)
           ^^^^^^^^^^^^^^^^^^^^^^^^^^^
  File "/home/airflow/.local/lib/python3.12/site-packages/airflow/operators/python.py", line 238, in execute
    return_value = self.execute_callable()
                   ^^^^^^^^^^^^^^^^^^^^^^^
  File "/home/airflow/.local/lib/python3.12/site-packages/airflow/operators/python.py", line 256, in execute_callable
    return runner.run(*self.op_args, **self.op_kwargs)
           ^^^^^^^^^^^^^^^^^^^^^^^^^^^^^^^^^^^^^^^^^^^
  File "/home/airflow/.local/lib/python3.12/site-packages/airflow/utils/operator_helpers.py", line 252, in run
    return self.func(*args, **kwargs)
           ^^^^^^^^^^^^^^^^^^^^^^^^^^
  File "/opt/airflow/dags/scripts/python_scripts.py", line 179, in load_to_gold_layer
    columns = [desc[0] for desc in conn.execute("DESCRIBE my_table").fetchall()]
                                   ^^^^^^^^^^^^^^^^^^^^^^^^^^^^^^^^^
duckdb.duckdb.CatalogException: Catalog Error: Table with name my_table does not exist!
Did you mean "pg_tables"?

LINE 1: DESCRIBE my_table
                 ^
[2025-03-08T20:16:00.448+0000] {local_task_job_runner.py:266} INFO - Task exited with return code 1
[2025-03-08T20:16:00.548+0000] {taskinstance.py:3900} INFO - 0 downstream tasks scheduled from follow-on schedule check
[2025-03-08T20:16:00.567+0000] {local_task_job_runner.py:245} INFO - ::endgroup::
