[2025-04-05T01:20:59.652+0000] {local_task_job_runner.py:123} INFO - ::group::Pre task execution logs
[2025-04-05T01:20:59.708+0000] {taskinstance.py:2612} INFO - Dependencies all met for dep_context=non-requeueable deps ti=<TaskInstance: pull_data_from_chess_api.load_dim_time_control manual__2025-04-05T01:20:19.392730+00:00 [queued]>
[2025-04-05T01:20:59.746+0000] {taskinstance.py:2612} INFO - Dependencies all met for dep_context=requeueable deps ti=<TaskInstance: pull_data_from_chess_api.load_dim_time_control manual__2025-04-05T01:20:19.392730+00:00 [queued]>
[2025-04-05T01:20:59.750+0000] {taskinstance.py:2865} INFO - Starting attempt 1 of 2
[2025-04-05T01:20:59.803+0000] {taskinstance.py:2888} INFO - Executing <Task(PythonOperator): load_dim_time_control> on 2025-04-05 01:20:19.392730+00:00
[2025-04-05T01:20:59.822+0000] {warnings.py:112} WARNING - /home/***/.local/lib/python3.12/site-packages/***/task/task_runner/standard_task_runner.py:70: DeprecationWarning: This process (pid=141) is multi-threaded, use of fork() may lead to deadlocks in the child.
  pid = os.fork()

[2025-04-05T01:20:59.827+0000] {standard_task_runner.py:72} INFO - Started process 241 to run task
[2025-04-05T01:20:59.830+0000] {standard_task_runner.py:104} INFO - Running: ['***', 'tasks', 'run', 'pull_data_from_chess_api', 'load_dim_time_control', 'manual__2025-04-05T01:20:19.392730+00:00', '--job-id', '1152', '--raw', '--subdir', 'DAGS_FOLDER/collect_chess_data_dag.py', '--cfg-path', '/tmp/tmp1belnxh5']
[2025-04-05T01:20:59.837+0000] {standard_task_runner.py:105} INFO - Job 1152: Subtask load_dim_time_control
[2025-04-05T01:20:59.948+0000] {task_command.py:467} INFO - Running <TaskInstance: pull_data_from_chess_api.load_dim_time_control manual__2025-04-05T01:20:19.392730+00:00 [running]> on host b1f5b949bce4
[2025-04-05T01:21:00.095+0000] {taskinstance.py:3131} INFO - Exporting env vars: AIRFLOW_CTX_DAG_OWNER='***' AIRFLOW_CTX_DAG_ID='pull_data_from_chess_api' AIRFLOW_CTX_TASK_ID='load_dim_time_control' AIRFLOW_CTX_EXECUTION_DATE='2025-04-05T01:20:19.392730+00:00' AIRFLOW_CTX_TRY_NUMBER='1' AIRFLOW_CTX_DAG_RUN_ID='manual__2025-04-05T01:20:19.392730+00:00'
[2025-04-05T01:21:00.097+0000] {taskinstance.py:731} INFO - ::endgroup::
[2025-04-05T01:21:00.114+0000] {logging_mixin.py:190} INFO - Received File Name: silver/fact-2025-04-games.parquet
[2025-04-05T01:21:00.176+0000] {connection.py:531} ERROR - Unable to retrieve connection from secrets backend (EnvironmentVariablesBackend). Checking subsequent secrets backend.
Traceback (most recent call last):
  File "/home/airflow/.local/lib/python3.12/site-packages/airflow/models/connection.py", line 526, in get_connection_from_secrets
    conn = secrets_backend.get_connection(conn_id=conn_id)
           ^^^^^^^^^^^^^^^^^^^^^^^^^^^^^^^^^^^^^^^^^^^^^^^
  File "/home/airflow/.local/lib/python3.12/site-packages/airflow/secrets/base_secrets.py", line 116, in get_connection
    return self.deserialize_connection(conn_id=conn_id, value=value)
           ^^^^^^^^^^^^^^^^^^^^^^^^^^^^^^^^^^^^^^^^^^^^^^^^^^^^^^^^^
  File "/home/airflow/.local/lib/python3.12/site-packages/airflow/secrets/base_secrets.py", line 70, in deserialize_connection
    return Connection(conn_id=conn_id, uri=value)
           ^^^^^^^^^^^^^^^^^^^^^^^^^^^^^^^^^^^^^^
  File "<string>", line 4, in __init__
  File "/home/airflow/.local/lib/python3.12/site-packages/sqlalchemy/orm/state.py", line 481, in _initialize_instance
    with util.safe_reraise():
         ^^^^^^^^^^^^^^^^^^^
  File "/home/airflow/.local/lib/python3.12/site-packages/sqlalchemy/util/langhelpers.py", line 70, in __exit__
    compat.raise_(
  File "/home/airflow/.local/lib/python3.12/site-packages/sqlalchemy/util/compat.py", line 211, in raise_
    raise exception
  File "/home/airflow/.local/lib/python3.12/site-packages/sqlalchemy/orm/state.py", line 479, in _initialize_instance
    return manager.original_init(*mixed[1:], **kwargs)
           ^^^^^^^^^^^^^^^^^^^^^^^^^^^^^^^^^^^^^^^^^^^
  File "/home/airflow/.local/lib/python3.12/site-packages/airflow/models/connection.py", line 169, in __init__
    self._parse_from_uri(uri)
  File "/home/airflow/.local/lib/python3.12/site-packages/airflow/models/connection.py", line 257, in _parse_from_uri
    self.port = uri_parts.port
                ^^^^^^^^^^^^^^
  File "/usr/local/lib/python3.12/urllib/parse.py", line 182, in port
    raise ValueError(f"Port could not be cast to integer value as {port!r}")
ValueError: Port could not be cast to integer value as 'DefaultEndpointsProtocol=https;AccountName=rbchesssa;AccountKey=lG9W+utkpTNorE0rTLlfDMUZsTPleXk6pXv6NnfDTi'
[2025-04-05T01:21:00.191+0000] {base.py:84} INFO - Retrieving connection 'azure_chess_storage'
[2025-04-05T01:21:09.454+0000] {logging_mixin.py:190} INFO - File To be loaded has (10, 2)
[2025-04-05T01:21:12.813+0000] {logging_mixin.py:190} INFO - Successfully Loaded to Azure Storage as gold/dim_time_control.parquet
[2025-04-05T01:21:12.821+0000] {python.py:240} INFO - Done. Returned value was: None
[2025-04-05T01:21:12.838+0000] {taskinstance.py:340} INFO - ::group::Post task execution logs
[2025-04-05T01:21:12.838+0000] {taskinstance.py:352} INFO - Marking task as SUCCESS. dag_id=pull_data_from_chess_api, task_id=load_dim_time_control, run_id=manual__2025-04-05T01:20:19.392730+00:00, execution_date=20250405T012019, start_date=20250405T012059, end_date=20250405T012112
[2025-04-05T01:21:12.888+0000] {local_task_job_runner.py:266} INFO - Task exited with return code 0
[2025-04-05T01:21:12.940+0000] {taskinstance.py:3900} INFO - 1 downstream tasks scheduled from follow-on schedule check
[2025-04-05T01:21:12.944+0000] {local_task_job_runner.py:245} INFO - ::endgroup::
