[2025-03-31T17:58:44.309+0000] {local_task_job_runner.py:123} INFO - ::group::Pre task execution logs
[2025-03-31T17:58:44.350+0000] {taskinstance.py:2612} INFO - Dependencies all met for dep_context=non-requeueable deps ti=<TaskInstance: pull_data_from_chess_api.load_fact_table scheduled__2023-12-01T00:00:00+00:00 [queued]>
[2025-03-31T17:58:44.369+0000] {taskinstance.py:2612} INFO - Dependencies all met for dep_context=requeueable deps ti=<TaskInstance: pull_data_from_chess_api.load_fact_table scheduled__2023-12-01T00:00:00+00:00 [queued]>
[2025-03-31T17:58:44.370+0000] {taskinstance.py:2865} INFO - Starting attempt 1 of 2
[2025-03-31T17:58:44.399+0000] {taskinstance.py:2888} INFO - Executing <Task(PythonOperator): load_fact_table> on 2023-12-01 00:00:00+00:00
[2025-03-31T17:58:44.414+0000] {warnings.py:112} WARNING - /home/***/.local/lib/python3.12/site-packages/***/task/task_runner/standard_task_runner.py:70: DeprecationWarning: This process (pid=12935) is multi-threaded, use of fork() may lead to deadlocks in the child.
  pid = os.fork()

[2025-03-31T17:58:44.418+0000] {standard_task_runner.py:72} INFO - Started process 12944 to run task
[2025-03-31T17:58:44.419+0000] {standard_task_runner.py:104} INFO - Running: ['***', 'tasks', 'run', 'pull_data_from_chess_api', 'load_fact_table', 'scheduled__2023-12-01T00:00:00+00:00', '--job-id', '1016', '--raw', '--subdir', 'DAGS_FOLDER/collect_chess_data_dag.py', '--cfg-path', '/tmp/tmpxtzc314d']
[2025-03-31T17:58:44.424+0000] {standard_task_runner.py:105} INFO - Job 1016: Subtask load_fact_table
[2025-03-31T17:58:44.516+0000] {task_command.py:467} INFO - Running <TaskInstance: pull_data_from_chess_api.load_fact_table scheduled__2023-12-01T00:00:00+00:00 [running]> on host 3b3ac09dc50a
[2025-03-31T17:58:44.753+0000] {taskinstance.py:3131} INFO - Exporting env vars: AIRFLOW_CTX_DAG_OWNER='***' AIRFLOW_CTX_DAG_ID='pull_data_from_chess_api' AIRFLOW_CTX_TASK_ID='load_fact_table' AIRFLOW_CTX_EXECUTION_DATE='2023-12-01T00:00:00+00:00' AIRFLOW_CTX_TRY_NUMBER='1' AIRFLOW_CTX_DAG_RUN_ID='scheduled__2023-12-01T00:00:00+00:00'
[2025-03-31T17:58:44.758+0000] {taskinstance.py:731} INFO - ::endgroup::
[2025-03-31T17:58:44.798+0000] {logging_mixin.py:190} INFO - 2023-12-01 00:00:00+00:00
[2025-03-31T17:58:44.799+0000] {logging_mixin.py:190} INFO - Received File Name: silver/fact-2023-12-games.parquet
[2025-03-31T17:58:44.964+0000] {connection.py:531} ERROR - Unable to retrieve connection from secrets backend (EnvironmentVariablesBackend). Checking subsequent secrets backend.
Traceback (most recent call last):
  File "/home/airflow/.local/lib/python3.12/site-packages/airflow/models/connection.py", line 526, in get_connection_from_secrets
    conn = secrets_backend.get_connection(conn_id=conn_id)
           ^^^^^^^^^^^^^^^^^^^^^^^^^^^^^^^^^^^^^^^^^^^^^^^
  File "/home/airflow/.local/lib/python3.12/site-packages/airflow/secrets/base_secrets.py", line 116, in get_connection
    return self.deserialize_connection(conn_id=conn_id, value=value)
           ^^^^^^^^^^^^^^^^^^^^^^^^^^^^^^^^^^^^^^^^^^^^^^^^^^^^^^^^^
  File "/home/airflow/.local/lib/python3.12/site-packages/airflow/secrets/base_secrets.py", line 70, in deserialize_connection
    return Connection(conn_id=conn_id, uri=value)
           ^^^^^^^^^^^^^^^^^^^^^^^^^^^^^^^^^^^^^^
  File "<string>", line 4, in __init__
  File "/home/airflow/.local/lib/python3.12/site-packages/sqlalchemy/orm/state.py", line 481, in _initialize_instance
    with util.safe_reraise():
         ^^^^^^^^^^^^^^^^^^^
  File "/home/airflow/.local/lib/python3.12/site-packages/sqlalchemy/util/langhelpers.py", line 70, in __exit__
    compat.raise_(
  File "/home/airflow/.local/lib/python3.12/site-packages/sqlalchemy/util/compat.py", line 211, in raise_
    raise exception
  File "/home/airflow/.local/lib/python3.12/site-packages/sqlalchemy/orm/state.py", line 479, in _initialize_instance
    return manager.original_init(*mixed[1:], **kwargs)
           ^^^^^^^^^^^^^^^^^^^^^^^^^^^^^^^^^^^^^^^^^^^
  File "/home/airflow/.local/lib/python3.12/site-packages/airflow/models/connection.py", line 169, in __init__
    self._parse_from_uri(uri)
  File "/home/airflow/.local/lib/python3.12/site-packages/airflow/models/connection.py", line 257, in _parse_from_uri
    self.port = uri_parts.port
                ^^^^^^^^^^^^^^
  File "/usr/local/lib/python3.12/urllib/parse.py", line 182, in port
    raise ValueError(f"Port could not be cast to integer value as {port!r}")
ValueError: Port could not be cast to integer value as 'DefaultEndpointsProtocol=https;AccountName=rbchesssa;AccountKey=lG9W+utkpTNorE0rTLlfDMUZsTPleXk6pXv6NnfDTi'
[2025-03-31T17:58:44.996+0000] {base.py:84} INFO - Retrieving connection 'azure_chess_storage'
[2025-03-31T17:59:07.619+0000] {logging_mixin.py:190} INFO - fact table to be added has: (348, 15)
[2025-03-31T17:59:10.133+0000] {logging_mixin.py:190} INFO - The Previous fact table has : (2596, 15)
[2025-03-31T17:59:27.257+0000] {logging_mixin.py:190} INFO - Both Tables have: (2944, 15)
[2025-03-31T17:59:41.440+0000] {logging_mixin.py:190} INFO - File To be loaded has (2944, 15)
[2025-03-31T17:59:45.255+0000] {logging_mixin.py:190} INFO - Successfully Loaded to Azure Storage as gold/fact-games.parquet
[2025-03-31T17:59:45.273+0000] {python.py:240} INFO - Done. Returned value was: None
[2025-03-31T17:59:45.323+0000] {taskinstance.py:340} INFO - ::group::Post task execution logs
[2025-03-31T17:59:45.323+0000] {taskinstance.py:352} INFO - Marking task as SUCCESS. dag_id=pull_data_from_chess_api, task_id=load_fact_table, run_id=scheduled__2023-12-01T00:00:00+00:00, execution_date=20231201T000000, start_date=20250331T175844, end_date=20250331T175945
[2025-03-31T17:59:45.448+0000] {local_task_job_runner.py:266} INFO - Task exited with return code 0
[2025-03-31T17:59:45.482+0000] {taskinstance.py:3900} INFO - 0 downstream tasks scheduled from follow-on schedule check
[2025-03-31T17:59:45.485+0000] {local_task_job_runner.py:245} INFO - ::endgroup::
