[2025-03-11T13:06:26.176+0000] {local_task_job_runner.py:123} INFO - ::group::Pre task execution logs
[2025-03-11T13:06:26.209+0000] {taskinstance.py:2612} INFO - Dependencies all met for dep_context=non-requeueable deps ti=<TaskInstance: load_data_warehouse.create_data_warehouse manual__2025-03-11T13:04:55.437711+00:00 [queued]>
[2025-03-11T13:06:26.223+0000] {taskinstance.py:2612} INFO - Dependencies all met for dep_context=requeueable deps ti=<TaskInstance: load_data_warehouse.create_data_warehouse manual__2025-03-11T13:04:55.437711+00:00 [queued]>
[2025-03-11T13:06:26.224+0000] {taskinstance.py:2865} INFO - Starting attempt 3 of 4
[2025-03-11T13:06:26.251+0000] {taskinstance.py:2888} INFO - Executing <Task(PostgresOperator): create_data_warehouse> on 2025-03-11 13:04:55.437711+00:00
[2025-03-11T13:06:26.269+0000] {warnings.py:112} WARNING - /home/***/.local/lib/python3.12/site-packages/***/task/task_runner/standard_task_runner.py:70: DeprecationWarning: This process (pid=31046) is multi-threaded, use of fork() may lead to deadlocks in the child.
  pid = os.fork()

[2025-03-11T13:06:26.271+0000] {standard_task_runner.py:72} INFO - Started process 31048 to run task
[2025-03-11T13:06:26.273+0000] {standard_task_runner.py:104} INFO - Running: ['***', 'tasks', 'run', 'load_data_warehouse', 'create_data_warehouse', 'manual__2025-03-11T13:04:55.437711+00:00', '--job-id', '569', '--raw', '--subdir', 'DAGS_FOLDER/load_data_warehouse_dag.py', '--cfg-path', '/tmp/tmpa7d75owe']
[2025-03-11T13:06:26.279+0000] {standard_task_runner.py:105} INFO - Job 569: Subtask create_data_warehouse
[2025-03-11T13:06:26.385+0000] {task_command.py:467} INFO - Running <TaskInstance: load_data_warehouse.create_data_warehouse manual__2025-03-11T13:04:55.437711+00:00 [running]> on host 70b3b9cfbba0
[2025-03-11T13:06:26.608+0000] {taskinstance.py:3131} INFO - Exporting env vars: AIRFLOW_CTX_DAG_OWNER='***' AIRFLOW_CTX_DAG_ID='load_data_warehouse' AIRFLOW_CTX_TASK_ID='create_data_warehouse' AIRFLOW_CTX_EXECUTION_DATE='2025-03-11T13:04:55.437711+00:00' AIRFLOW_CTX_TRY_NUMBER='3' AIRFLOW_CTX_DAG_RUN_ID='manual__2025-03-11T13:04:55.437711+00:00'
[2025-03-11T13:06:26.612+0000] {taskinstance.py:731} INFO - ::endgroup::
[2025-03-11T13:06:26.628+0000] {sql.py:266} INFO - Executing: -- Fact Tables Creating
CREATE SCHEMA IF NOT EXISTS chess_dw;
CREATE TABLE IF NOT EXISTS chess_dw.fact_games (
    game_url INT PRIMARY KEY,
    time_control VARCHAR,
    rated BOOLEAN,
    time_class VARCHAR,
    rules VARCHAR,
    white_rating INT,
    white_result VARCHAR(10),
    black_rating INT,
    black_result VARCHAR(10),
    pgn_event VARCHAR,
    pgn_site VARCHAR,
    game_date DATE,
    pgn_white_user VARCHAR,
    pgn_black_user VARCHAR,
    pgn_result VARCHAR,
    pgn_current_position VARCHAR,
    pgn_timezone VARCHAR,
    pgn_eco VARCHAR,
    pgn_eco_url VARCHAR,
    start_time TIMESTAMP,
    end_time TIMESTAMP,
    end_game_date TIMESTAMP
);


-- Dimension tables creation
CREATE TABLE IF NOT EXISTS chess_dw.dim_date (
    id_dim_date INTEGER,
    game_date DATE,
    day VARCHAR,
    day_of_week VARCHAR,
    day_of_month VARCHAR,
    month VARCHAR,
    month_name VARCHAR,
    quarter VARCHAR,
    year VARCHAR,
    is_weekend VARCHAR,
);


CREATE TABLE IF NOT EXISTS chess_dw.dim_openings (
    eco_pgn VARCHAR PRIMARY KEY, 
    opening_letter VARCHAR(1),
    eco_family_code VARCHAR(3),
    eco_full_name VARCHAR,
    eco_shortname VARCHAR
);


CREATE TABLE IF NOT EXISTS chess_dw.dim_users (
    user_id VARCHAR PRIMARY KEY
    full_name VARCHAR
    Nationality VARCHAR
);
[2025-03-11T13:06:26.671+0000] {base.py:84} INFO - Retrieving connection 'azure_chess_dw'
[2025-03-11T13:06:26.703+0000] {base.py:84} INFO - Retrieving connection 'azure_chess_dw'
[2025-03-11T13:06:48.657+0000] {taskinstance.py:3310} ERROR - Task failed with exception
Traceback (most recent call last):
  File "/home/airflow/.local/lib/python3.12/site-packages/airflow/models/taskinstance.py", line 767, in _execute_task
    result = _execute_callable(context=context, **execute_callable_kwargs)
             ^^^^^^^^^^^^^^^^^^^^^^^^^^^^^^^^^^^^^^^^^^^^^^^^^^^^^^^^^^^^^
  File "/home/airflow/.local/lib/python3.12/site-packages/airflow/models/taskinstance.py", line 733, in _execute_callable
    return ExecutionCallableRunner(
           ^^^^^^^^^^^^^^^^^^^^^^^^
  File "/home/airflow/.local/lib/python3.12/site-packages/airflow/utils/operator_helpers.py", line 252, in run
    return self.func(*args, **kwargs)
           ^^^^^^^^^^^^^^^^^^^^^^^^^^
  File "/home/airflow/.local/lib/python3.12/site-packages/airflow/models/baseoperator.py", line 406, in wrapper
    return func(self, *args, **kwargs)
           ^^^^^^^^^^^^^^^^^^^^^^^^^^^
  File "/home/airflow/.local/lib/python3.12/site-packages/airflow/providers/common/sql/operators/sql.py", line 272, in execute
    output = hook.run(
             ^^^^^^^^^
  File "/home/airflow/.local/lib/python3.12/site-packages/airflow/providers/common/sql/hooks/sql.py", line 452, in run
    with self._create_autocommit_connection(autocommit) as conn:
         ^^^^^^^^^^^^^^^^^^^^^^^^^^^^^^^^^^^^^^^^^^^^^^
  File "/usr/local/lib/python3.12/contextlib.py", line 137, in __enter__
    return next(self.gen)
           ^^^^^^^^^^^^^^
  File "/home/airflow/.local/lib/python3.12/site-packages/airflow/providers/common/sql/hooks/sql.py", line 574, in _create_autocommit_connection
    with closing(self.get_conn()) as conn:
                 ^^^^^^^^^^^^^^^
  File "/home/airflow/.local/lib/python3.12/site-packages/airflow/providers/postgres/hooks/postgres.py", line 176, in get_conn
    self.conn = psycopg2.connect(**conn_args)
                ^^^^^^^^^^^^^^^^^^^^^^^^^^^^^
  File "/home/airflow/.local/lib/python3.12/site-packages/psycopg2/__init__.py", line 122, in connect
    conn = _connect(dsn, connection_factory=connection_factory, **kwasync)
           ^^^^^^^^^^^^^^^^^^^^^^^^^^^^^^^^^^^^^^^^^^^^^^^^^^^^^^^^^^^^^^^
psycopg2.OperationalError: connection to server at "chess-dw.postgres.database.azure.com" (40.75.102.191), port 5432 failed: Connection refused
	Is the server running on that host and accepting TCP/IP connections?

[2025-03-11T13:06:49.958+0000] {taskinstance.py:1225} INFO - Marking task as UP_FOR_RETRY. dag_id=load_data_warehouse, task_id=create_data_warehouse, run_id=manual__2025-03-11T13:04:55.437711+00:00, execution_date=20250311T130455, start_date=20250311T130626, end_date=20250311T130649
[2025-03-11T13:06:50.065+0000] {taskinstance.py:340} INFO - ::group::Post task execution logs
[2025-03-11T13:06:50.067+0000] {standard_task_runner.py:124} ERROR - Failed to execute job 569 for task create_data_warehouse (connection to server at "chess-dw.postgres.database.azure.com" (40.75.102.191), port 5432 failed: Connection refused
	Is the server running on that host and accepting TCP/IP connections?
; 31048)
Traceback (most recent call last):
  File "/home/airflow/.local/lib/python3.12/site-packages/airflow/task/task_runner/standard_task_runner.py", line 117, in _start_by_fork
    ret = args.func(args, dag=self.dag)
          ^^^^^^^^^^^^^^^^^^^^^^^^^^^^^
  File "/home/airflow/.local/lib/python3.12/site-packages/airflow/cli/cli_config.py", line 49, in command
    return func(*args, **kwargs)
           ^^^^^^^^^^^^^^^^^^^^^
  File "/home/airflow/.local/lib/python3.12/site-packages/airflow/utils/cli.py", line 115, in wrapper
    return f(*args, **kwargs)
           ^^^^^^^^^^^^^^^^^^
  File "/home/airflow/.local/lib/python3.12/site-packages/airflow/cli/commands/task_command.py", line 483, in task_run
    task_return_code = _run_task_by_selected_method(args, _dag, ti)
                       ^^^^^^^^^^^^^^^^^^^^^^^^^^^^^^^^^^^^^^^^^^^^
  File "/home/airflow/.local/lib/python3.12/site-packages/airflow/cli/commands/task_command.py", line 256, in _run_task_by_selected_method
    return _run_raw_task(args, ti)
           ^^^^^^^^^^^^^^^^^^^^^^^
  File "/home/airflow/.local/lib/python3.12/site-packages/airflow/cli/commands/task_command.py", line 341, in _run_raw_task
    return ti._run_raw_task(
           ^^^^^^^^^^^^^^^^^
  File "/home/airflow/.local/lib/python3.12/site-packages/airflow/utils/session.py", line 97, in wrapper
    return func(*args, session=session, **kwargs)
           ^^^^^^^^^^^^^^^^^^^^^^^^^^^^^^^^^^^^^^
  File "/home/airflow/.local/lib/python3.12/site-packages/airflow/models/taskinstance.py", line 3004, in _run_raw_task
    return _run_raw_task(
           ^^^^^^^^^^^^^^
  File "/home/airflow/.local/lib/python3.12/site-packages/airflow/models/taskinstance.py", line 273, in _run_raw_task
    TaskInstance._execute_task_with_callbacks(
  File "/home/airflow/.local/lib/python3.12/site-packages/airflow/models/taskinstance.py", line 3158, in _execute_task_with_callbacks
    result = self._execute_task(context, task_orig)
             ^^^^^^^^^^^^^^^^^^^^^^^^^^^^^^^^^^^^^^
  File "/home/airflow/.local/lib/python3.12/site-packages/airflow/models/taskinstance.py", line 3182, in _execute_task
    return _execute_task(self, context, task_orig)
           ^^^^^^^^^^^^^^^^^^^^^^^^^^^^^^^^^^^^^^^
  File "/home/airflow/.local/lib/python3.12/site-packages/airflow/models/taskinstance.py", line 767, in _execute_task
    result = _execute_callable(context=context, **execute_callable_kwargs)
             ^^^^^^^^^^^^^^^^^^^^^^^^^^^^^^^^^^^^^^^^^^^^^^^^^^^^^^^^^^^^^
  File "/home/airflow/.local/lib/python3.12/site-packages/airflow/models/taskinstance.py", line 733, in _execute_callable
    return ExecutionCallableRunner(
           ^^^^^^^^^^^^^^^^^^^^^^^^
  File "/home/airflow/.local/lib/python3.12/site-packages/airflow/utils/operator_helpers.py", line 252, in run
    return self.func(*args, **kwargs)
           ^^^^^^^^^^^^^^^^^^^^^^^^^^
  File "/home/airflow/.local/lib/python3.12/site-packages/airflow/models/baseoperator.py", line 406, in wrapper
    return func(self, *args, **kwargs)
           ^^^^^^^^^^^^^^^^^^^^^^^^^^^
  File "/home/airflow/.local/lib/python3.12/site-packages/airflow/providers/common/sql/operators/sql.py", line 272, in execute
    output = hook.run(
             ^^^^^^^^^
  File "/home/airflow/.local/lib/python3.12/site-packages/airflow/providers/common/sql/hooks/sql.py", line 452, in run
    with self._create_autocommit_connection(autocommit) as conn:
         ^^^^^^^^^^^^^^^^^^^^^^^^^^^^^^^^^^^^^^^^^^^^^^
  File "/usr/local/lib/python3.12/contextlib.py", line 137, in __enter__
    return next(self.gen)
           ^^^^^^^^^^^^^^
  File "/home/airflow/.local/lib/python3.12/site-packages/airflow/providers/common/sql/hooks/sql.py", line 574, in _create_autocommit_connection
    with closing(self.get_conn()) as conn:
                 ^^^^^^^^^^^^^^^
  File "/home/airflow/.local/lib/python3.12/site-packages/airflow/providers/postgres/hooks/postgres.py", line 176, in get_conn
    self.conn = psycopg2.connect(**conn_args)
                ^^^^^^^^^^^^^^^^^^^^^^^^^^^^^
  File "/home/airflow/.local/lib/python3.12/site-packages/psycopg2/__init__.py", line 122, in connect
    conn = _connect(dsn, connection_factory=connection_factory, **kwasync)
           ^^^^^^^^^^^^^^^^^^^^^^^^^^^^^^^^^^^^^^^^^^^^^^^^^^^^^^^^^^^^^^^
psycopg2.OperationalError: connection to server at "chess-dw.postgres.database.azure.com" (40.75.102.191), port 5432 failed: Connection refused
	Is the server running on that host and accepting TCP/IP connections?

[2025-03-11T13:06:50.173+0000] {local_task_job_runner.py:266} INFO - Task exited with return code 1
[2025-03-11T13:06:50.247+0000] {taskinstance.py:3900} INFO - 0 downstream tasks scheduled from follow-on schedule check
[2025-03-11T13:06:50.253+0000] {local_task_job_runner.py:245} INFO - ::endgroup::
