[2025-03-26T02:11:26.145+0000] {local_task_job_runner.py:123} INFO - ::group::Pre task execution logs
[2025-03-26T02:11:26.193+0000] {taskinstance.py:2612} INFO - Dependencies all met for dep_context=non-requeueable deps ti=<TaskInstance: load_data_warehouse.get_last_updated_date manual__2025-03-12T14:13:58.419334+00:00 [queued]>
[2025-03-26T02:11:26.222+0000] {taskinstance.py:2612} INFO - Dependencies all met for dep_context=requeueable deps ti=<TaskInstance: load_data_warehouse.get_last_updated_date manual__2025-03-12T14:13:58.419334+00:00 [queued]>
[2025-03-26T02:11:26.223+0000] {taskinstance.py:2865} INFO - Starting attempt 13 of 13
[2025-03-26T02:11:26.261+0000] {taskinstance.py:2888} INFO - Executing <Task(PostgresOperator): get_last_updated_date> on 2025-03-12 14:13:58.419334+00:00
[2025-03-26T02:11:26.280+0000] {warnings.py:112} WARNING - /home/***/.local/lib/python3.12/site-packages/***/task/task_runner/standard_task_runner.py:70: DeprecationWarning: This process (pid=29840) is multi-threaded, use of fork() may lead to deadlocks in the child.
  pid = os.fork()

[2025-03-26T02:11:26.286+0000] {standard_task_runner.py:72} INFO - Started process 29849 to run task
[2025-03-26T02:11:26.286+0000] {standard_task_runner.py:104} INFO - Running: ['***', 'tasks', 'run', 'load_data_warehouse', 'get_last_updated_date', 'manual__2025-03-12T14:13:58.419334+00:00', '--job-id', '766', '--raw', '--subdir', 'DAGS_FOLDER/load_data_warehouse_dag.py', '--cfg-path', '/tmp/tmpeyoiwqwb']
[2025-03-26T02:11:26.295+0000] {standard_task_runner.py:105} INFO - Job 766: Subtask get_last_updated_date
[2025-03-26T02:11:26.488+0000] {task_command.py:467} INFO - Running <TaskInstance: load_data_warehouse.get_last_updated_date manual__2025-03-12T14:13:58.419334+00:00 [running]> on host 8de4e0a4beb2
[2025-03-26T02:11:27.144+0000] {taskinstance.py:3131} INFO - Exporting env vars: AIRFLOW_CTX_DAG_OWNER='***' AIRFLOW_CTX_DAG_ID='load_data_warehouse' AIRFLOW_CTX_TASK_ID='get_last_updated_date' AIRFLOW_CTX_EXECUTION_DATE='2025-03-12T14:13:58.419334+00:00' AIRFLOW_CTX_TRY_NUMBER='13' AIRFLOW_CTX_DAG_RUN_ID='manual__2025-03-12T14:13:58.419334+00:00'
[2025-03-26T02:11:27.150+0000] {taskinstance.py:731} INFO - ::endgroup::
[2025-03-26T02:11:27.163+0000] {sql.py:266} INFO - Executing: SELECT last_updated FROM chess_dw.fact_games ORDER BY last_updated DESC LIMIT 1;
[2025-03-26T02:11:27.199+0000] {base.py:84} INFO - Retrieving connection 'azure_chess_dw'
[2025-03-26T02:11:27.242+0000] {base.py:84} INFO - Retrieving connection 'azure_chess_dw'
[2025-03-26T02:11:30.284+0000] {sql.py:509} INFO - Running statement: SELECT last_updated FROM chess_dw.fact_games ORDER BY last_updated DESC LIMIT 1;, parameters: None
[2025-03-26T02:11:30.703+0000] {taskinstance.py:3310} ERROR - Task failed with exception
Traceback (most recent call last):
  File "/home/airflow/.local/lib/python3.12/site-packages/airflow/models/taskinstance.py", line 767, in _execute_task
    result = _execute_callable(context=context, **execute_callable_kwargs)
             ^^^^^^^^^^^^^^^^^^^^^^^^^^^^^^^^^^^^^^^^^^^^^^^^^^^^^^^^^^^^^
  File "/home/airflow/.local/lib/python3.12/site-packages/airflow/models/taskinstance.py", line 733, in _execute_callable
    return ExecutionCallableRunner(
           ^^^^^^^^^^^^^^^^^^^^^^^^
  File "/home/airflow/.local/lib/python3.12/site-packages/airflow/utils/operator_helpers.py", line 252, in run
    return self.func(*args, **kwargs)
           ^^^^^^^^^^^^^^^^^^^^^^^^^^
  File "/home/airflow/.local/lib/python3.12/site-packages/airflow/models/baseoperator.py", line 406, in wrapper
    return func(self, *args, **kwargs)
           ^^^^^^^^^^^^^^^^^^^^^^^^^^^
  File "/home/airflow/.local/lib/python3.12/site-packages/airflow/providers/common/sql/operators/sql.py", line 272, in execute
    output = hook.run(
             ^^^^^^^^^
  File "/home/airflow/.local/lib/python3.12/site-packages/airflow/providers/common/sql/hooks/sql.py", line 456, in run
    self._run_command(cur, sql_statement, parameters)
  File "/home/airflow/.local/lib/python3.12/site-packages/airflow/providers/common/sql/hooks/sql.py", line 514, in _run_command
    cur.execute(sql_statement)
psycopg2.errors.UndefinedTable: relation "chess_dw.fact_games" does not exist
LINE 1: SELECT last_updated FROM chess_dw.fact_games ORDER BY last_u...
                                 ^

[2025-03-26T02:11:30.744+0000] {taskinstance.py:1225} INFO - Marking task as UP_FOR_RETRY. dag_id=load_data_warehouse, task_id=get_last_updated_date, run_id=manual__2025-03-12T14:13:58.419334+00:00, execution_date=20250312T141358, start_date=20250326T021126, end_date=20250326T021130
[2025-03-26T02:11:30.811+0000] {taskinstance.py:340} INFO - ::group::Post task execution logs
[2025-03-26T02:11:30.814+0000] {standard_task_runner.py:124} ERROR - Failed to execute job 766 for task get_last_updated_date (relation "chess_dw.fact_games" does not exist
LINE 1: SELECT last_updated FROM chess_dw.fact_games ORDER BY last_u...
                                 ^
; 29849)
Traceback (most recent call last):
  File "/home/airflow/.local/lib/python3.12/site-packages/airflow/task/task_runner/standard_task_runner.py", line 117, in _start_by_fork
    ret = args.func(args, dag=self.dag)
          ^^^^^^^^^^^^^^^^^^^^^^^^^^^^^
  File "/home/airflow/.local/lib/python3.12/site-packages/airflow/cli/cli_config.py", line 49, in command
    return func(*args, **kwargs)
           ^^^^^^^^^^^^^^^^^^^^^
  File "/home/airflow/.local/lib/python3.12/site-packages/airflow/utils/cli.py", line 115, in wrapper
    return f(*args, **kwargs)
           ^^^^^^^^^^^^^^^^^^
  File "/home/airflow/.local/lib/python3.12/site-packages/airflow/cli/commands/task_command.py", line 483, in task_run
    task_return_code = _run_task_by_selected_method(args, _dag, ti)
                       ^^^^^^^^^^^^^^^^^^^^^^^^^^^^^^^^^^^^^^^^^^^^
  File "/home/airflow/.local/lib/python3.12/site-packages/airflow/cli/commands/task_command.py", line 256, in _run_task_by_selected_method
    return _run_raw_task(args, ti)
           ^^^^^^^^^^^^^^^^^^^^^^^
  File "/home/airflow/.local/lib/python3.12/site-packages/airflow/cli/commands/task_command.py", line 341, in _run_raw_task
    return ti._run_raw_task(
           ^^^^^^^^^^^^^^^^^
  File "/home/airflow/.local/lib/python3.12/site-packages/airflow/utils/session.py", line 97, in wrapper
    return func(*args, session=session, **kwargs)
           ^^^^^^^^^^^^^^^^^^^^^^^^^^^^^^^^^^^^^^
  File "/home/airflow/.local/lib/python3.12/site-packages/airflow/models/taskinstance.py", line 3004, in _run_raw_task
    return _run_raw_task(
           ^^^^^^^^^^^^^^
  File "/home/airflow/.local/lib/python3.12/site-packages/airflow/models/taskinstance.py", line 273, in _run_raw_task
    TaskInstance._execute_task_with_callbacks(
  File "/home/airflow/.local/lib/python3.12/site-packages/airflow/models/taskinstance.py", line 3158, in _execute_task_with_callbacks
    result = self._execute_task(context, task_orig)
             ^^^^^^^^^^^^^^^^^^^^^^^^^^^^^^^^^^^^^^
  File "/home/airflow/.local/lib/python3.12/site-packages/airflow/models/taskinstance.py", line 3182, in _execute_task
    return _execute_task(self, context, task_orig)
           ^^^^^^^^^^^^^^^^^^^^^^^^^^^^^^^^^^^^^^^
  File "/home/airflow/.local/lib/python3.12/site-packages/airflow/models/taskinstance.py", line 767, in _execute_task
    result = _execute_callable(context=context, **execute_callable_kwargs)
             ^^^^^^^^^^^^^^^^^^^^^^^^^^^^^^^^^^^^^^^^^^^^^^^^^^^^^^^^^^^^^
  File "/home/airflow/.local/lib/python3.12/site-packages/airflow/models/taskinstance.py", line 733, in _execute_callable
    return ExecutionCallableRunner(
           ^^^^^^^^^^^^^^^^^^^^^^^^
  File "/home/airflow/.local/lib/python3.12/site-packages/airflow/utils/operator_helpers.py", line 252, in run
    return self.func(*args, **kwargs)
           ^^^^^^^^^^^^^^^^^^^^^^^^^^
  File "/home/airflow/.local/lib/python3.12/site-packages/airflow/models/baseoperator.py", line 406, in wrapper
    return func(self, *args, **kwargs)
           ^^^^^^^^^^^^^^^^^^^^^^^^^^^
  File "/home/airflow/.local/lib/python3.12/site-packages/airflow/providers/common/sql/operators/sql.py", line 272, in execute
    output = hook.run(
             ^^^^^^^^^
  File "/home/airflow/.local/lib/python3.12/site-packages/airflow/providers/common/sql/hooks/sql.py", line 456, in run
    self._run_command(cur, sql_statement, parameters)
  File "/home/airflow/.local/lib/python3.12/site-packages/airflow/providers/common/sql/hooks/sql.py", line 514, in _run_command
    cur.execute(sql_statement)
psycopg2.errors.UndefinedTable: relation "chess_dw.fact_games" does not exist
LINE 1: SELECT last_updated FROM chess_dw.fact_games ORDER BY last_u...
                                 ^

[2025-03-26T02:11:30.894+0000] {local_task_job_runner.py:266} INFO - Task exited with return code 1
[2025-03-26T02:11:30.925+0000] {warnings.py:112} WARNING - /home/***/.local/lib/python3.12/site-packages/***/models/baseoperator.py:1378: AirflowProviderDeprecationWarning: Call to deprecated class PostgresOperator. (Please use `***.providers.common.sql.operators.sql.SQLExecuteQueryOperator`.Also, you can provide `hook_params={'schema': <database>}`.)
  result = cls.__new__(cls)

[2025-03-26T02:11:30.968+0000] {taskinstance.py:3900} INFO - 0 downstream tasks scheduled from follow-on schedule check
[2025-03-26T02:11:30.973+0000] {local_task_job_runner.py:245} INFO - ::endgroup::
