[2025-04-05T01:20:37.727+0000] {local_task_job_runner.py:123} INFO - ::group::Pre task execution logs
[2025-04-05T01:20:37.759+0000] {taskinstance.py:2612} INFO - Dependencies all met for dep_context=non-requeueable deps ti=<TaskInstance: pull_data_from_chess_api.transform_json_to_fact_table manual__2025-04-05T01:20:19.392730+00:00 [queued]>
[2025-04-05T01:20:37.778+0000] {taskinstance.py:2612} INFO - Dependencies all met for dep_context=requeueable deps ti=<TaskInstance: pull_data_from_chess_api.transform_json_to_fact_table manual__2025-04-05T01:20:19.392730+00:00 [queued]>
[2025-04-05T01:20:37.779+0000] {taskinstance.py:2865} INFO - Starting attempt 1 of 2
[2025-04-05T01:20:37.836+0000] {taskinstance.py:2888} INFO - Executing <Task(PythonOperator): transform_json_to_fact_table> on 2025-04-05 01:20:19.392730+00:00
[2025-04-05T01:20:37.865+0000] {warnings.py:112} WARNING - /home/***/.local/lib/python3.12/site-packages/***/task/task_runner/standard_task_runner.py:70: DeprecationWarning: This process (pid=97) is multi-threaded, use of fork() may lead to deadlocks in the child.
  pid = os.fork()

[2025-04-05T01:20:37.871+0000] {standard_task_runner.py:72} INFO - Started process 106 to run task
[2025-04-05T01:20:37.865+0000] {standard_task_runner.py:104} INFO - Running: ['***', 'tasks', 'run', 'pull_data_from_chess_api', 'transform_json_to_fact_table', 'manual__2025-04-05T01:20:19.392730+00:00', '--job-id', '1148', '--raw', '--subdir', 'DAGS_FOLDER/collect_chess_data_dag.py', '--cfg-path', '/tmp/tmp2gav5f6c']
[2025-04-05T01:20:37.873+0000] {standard_task_runner.py:105} INFO - Job 1148: Subtask transform_json_to_fact_table
[2025-04-05T01:20:38.024+0000] {task_command.py:467} INFO - Running <TaskInstance: pull_data_from_chess_api.transform_json_to_fact_table manual__2025-04-05T01:20:19.392730+00:00 [running]> on host b1f5b949bce4
[2025-04-05T01:20:38.253+0000] {taskinstance.py:3131} INFO - Exporting env vars: AIRFLOW_CTX_DAG_OWNER='***' AIRFLOW_CTX_DAG_ID='pull_data_from_chess_api' AIRFLOW_CTX_TASK_ID='transform_json_to_fact_table' AIRFLOW_CTX_EXECUTION_DATE='2025-04-05T01:20:19.392730+00:00' AIRFLOW_CTX_TRY_NUMBER='1' AIRFLOW_CTX_DAG_RUN_ID='manual__2025-04-05T01:20:19.392730+00:00'
[2025-04-05T01:20:38.257+0000] {taskinstance.py:731} INFO - ::endgroup::
[2025-04-05T01:20:38.293+0000] {connection.py:531} ERROR - Unable to retrieve connection from secrets backend (EnvironmentVariablesBackend). Checking subsequent secrets backend.
Traceback (most recent call last):
  File "/home/airflow/.local/lib/python3.12/site-packages/airflow/models/connection.py", line 526, in get_connection_from_secrets
    conn = secrets_backend.get_connection(conn_id=conn_id)
           ^^^^^^^^^^^^^^^^^^^^^^^^^^^^^^^^^^^^^^^^^^^^^^^
  File "/home/airflow/.local/lib/python3.12/site-packages/airflow/secrets/base_secrets.py", line 116, in get_connection
    return self.deserialize_connection(conn_id=conn_id, value=value)
           ^^^^^^^^^^^^^^^^^^^^^^^^^^^^^^^^^^^^^^^^^^^^^^^^^^^^^^^^^
  File "/home/airflow/.local/lib/python3.12/site-packages/airflow/secrets/base_secrets.py", line 70, in deserialize_connection
    return Connection(conn_id=conn_id, uri=value)
           ^^^^^^^^^^^^^^^^^^^^^^^^^^^^^^^^^^^^^^
  File "<string>", line 4, in __init__
  File "/home/airflow/.local/lib/python3.12/site-packages/sqlalchemy/orm/state.py", line 481, in _initialize_instance
    with util.safe_reraise():
         ^^^^^^^^^^^^^^^^^^^
  File "/home/airflow/.local/lib/python3.12/site-packages/sqlalchemy/util/langhelpers.py", line 70, in __exit__
    compat.raise_(
  File "/home/airflow/.local/lib/python3.12/site-packages/sqlalchemy/util/compat.py", line 211, in raise_
    raise exception
  File "/home/airflow/.local/lib/python3.12/site-packages/sqlalchemy/orm/state.py", line 479, in _initialize_instance
    return manager.original_init(*mixed[1:], **kwargs)
           ^^^^^^^^^^^^^^^^^^^^^^^^^^^^^^^^^^^^^^^^^^^
  File "/home/airflow/.local/lib/python3.12/site-packages/airflow/models/connection.py", line 169, in __init__
    self._parse_from_uri(uri)
  File "/home/airflow/.local/lib/python3.12/site-packages/airflow/models/connection.py", line 257, in _parse_from_uri
    self.port = uri_parts.port
                ^^^^^^^^^^^^^^
  File "/usr/local/lib/python3.12/urllib/parse.py", line 182, in port
    raise ValueError(f"Port could not be cast to integer value as {port!r}")
ValueError: Port could not be cast to integer value as 'DefaultEndpointsProtocol=https;AccountName=rbchesssa;AccountKey=lG9W+utkpTNorE0rTLlfDMUZsTPleXk6pXv6NnfDTi'
[2025-04-05T01:20:38.314+0000] {base.py:84} INFO - Retrieving connection 'azure_chess_storage'
[2025-04-05T01:20:40.957+0000] {logging_mixin.py:190} INFO - /tmp/tmpq3d9ph7q
[2025-04-05T01:20:42.011+0000] {logging_mixin.py:190} INFO - Successfully Transformed Data and Loaded to Azure Storage as silver/fact-2025-04-games.parquet
[2025-04-05T01:20:42.015+0000] {python.py:240} INFO - Done. Returned value was: None
[2025-04-05T01:20:42.047+0000] {taskinstance.py:340} INFO - ::group::Post task execution logs
[2025-04-05T01:20:42.048+0000] {taskinstance.py:352} INFO - Marking task as SUCCESS. dag_id=pull_data_from_chess_api, task_id=transform_json_to_fact_table, run_id=manual__2025-04-05T01:20:19.392730+00:00, execution_date=20250405T012019, start_date=20250405T012037, end_date=20250405T012042
[2025-04-05T01:20:42.119+0000] {local_task_job_runner.py:266} INFO - Task exited with return code 0
[2025-04-05T01:20:42.191+0000] {taskinstance.py:3900} INFO - 4 downstream tasks scheduled from follow-on schedule check
[2025-04-05T01:20:42.195+0000] {local_task_job_runner.py:245} INFO - ::endgroup::
